nohup: ignoring input
 * Serving Flask app 'app'
 * Debug mode: on
WARNING: This is a development server. Do not use it in a production deployment. Use a production WSGI server instead.
 * Running on all addresses (0.0.0.0)
 * Running on http://127.0.0.1:5000
 * Running on http://37.220.84.197:5000
Press CTRL+C to quit
 * Restarting with stat
 * Debugger is active!
 * Debugger PIN: 530-417-129
45.144.51.69 - - [01/Jul/2025 02:07:47] "GET /dashboard HTTP/1.1" 200 -
71.6.134.235 - - [01/Jul/2025 04:00:00] code 400, message Bad request version ('ÊÊ\x13\x01\x13\x02\x13\x03À+À/À,À0Ì©Ì¨À\x13À\x14\x00\x9c\x00\x9d\x00/\x005\x01\x00\x00{\x00\x05\x00\x05\x01\x00\x00\x00\x00\x00')
71.6.134.235 - - [01/Jul/2025 04:00:00] "\x16\x03\x01\x00è\x01\x00\x00ä\x03\x03\x9cÄúEÈB~ò¯¨4®¬Ñ%(Å\x8e\x80fÂ\x9f°q\x0f|V\x16\x81Üq\\ ã\x97.ôd¡ ½\x9bc\x9d¯\x93\x17ýÃR\x89®Ïq\x80\x18Ju[ÉæªF\x92}\x00 ÊÊ\x13\x01\x13\x02\x13\x03À+À/À,À0Ì©Ì¨À\x13À\x14\x00\x9c\x00\x9d\x00/\x005\x01\x00\x00{\x00\x05\x00\x05\x01\x00\x00\x00\x00\x00" HTTPStatus.BAD_REQUEST -
71.6.134.235 - - [01/Jul/2025 04:15:31] "GET / HTTP/1.1" 302 -
71.6.134.235 - - [01/Jul/2025 04:15:31] "GET /dashboard HTTP/1.1" 200 -
[2025-07-01 04:15:53,431] ERROR in app: Ошибка: 404 Not Found: The requested URL was not found on the server. If you entered the URL manually please check your spelling and try again.
71.6.134.235 - - [01/Jul/2025 04:15:53] "GET /favicon.ico HTTP/1.1" 500 -
Traceback (most recent call last):
  File "/usr/local/lib/python3.10/dist-packages/flask/app.py", line 917, in full_dispatch_request
    rv = self.dispatch_request()
  File "/usr/local/lib/python3.10/dist-packages/flask/app.py", line 891, in dispatch_request
    self.raise_routing_exception(req)
  File "/usr/local/lib/python3.10/dist-packages/flask/app.py", line 500, in raise_routing_exception
    raise request.routing_exception  # type: ignore[misc]
  File "/usr/local/lib/python3.10/dist-packages/flask/ctx.py", line 362, in match_request
    result = self.url_adapter.match(return_rule=True)  # type: ignore
  File "/usr/local/lib/python3.10/dist-packages/werkzeug/routing/map.py", line 629, in match
    raise NotFound() from None
werkzeug.exceptions.NotFound: 404 Not Found: The requested URL was not found on the server. If you entered the URL manually please check your spelling and try again.

During handling of the above exception, another exception occurred:

Traceback (most recent call last):
  File "/usr/local/lib/python3.10/dist-packages/flask/app.py", line 1536, in __call__
    return self.wsgi_app(environ, start_response)
  File "/usr/local/lib/python3.10/dist-packages/flask/app.py", line 1514, in wsgi_app
    response = self.handle_exception(e)
  File "/usr/local/lib/python3.10/dist-packages/flask/app.py", line 1511, in wsgi_app
    response = self.full_dispatch_request()
  File "/usr/local/lib/python3.10/dist-packages/flask/app.py", line 919, in full_dispatch_request
    rv = self.handle_user_exception(e)
  File "/usr/local/lib/python3.10/dist-packages/flask/app.py", line 802, in handle_user_exception
    return self.handle_http_exception(e)
  File "/usr/local/lib/python3.10/dist-packages/flask/app.py", line 777, in handle_http_exception
    return self.ensure_sync(handler)(e)  # type: ignore[no-any-return]
  File "/root/VFS-Global/site/app.py", line 32, in handle_exception
    return render_template("error.html", error=str(e)), 500
  File "/usr/local/lib/python3.10/dist-packages/flask/templating.py", line 149, in render_template
    template = app.jinja_env.get_or_select_template(template_name_or_list)
  File "/usr/local/lib/python3.10/dist-packages/jinja2/environment.py", line 1087, in get_or_select_template
    return self.get_template(template_name_or_list, parent, globals)
  File "/usr/local/lib/python3.10/dist-packages/jinja2/environment.py", line 1016, in get_template
    return self._load_template(name, globals)
  File "/usr/local/lib/python3.10/dist-packages/jinja2/environment.py", line 975, in _load_template
    template = self.loader.load(self, name, self.make_globals(globals))
  File "/usr/local/lib/python3.10/dist-packages/jinja2/loaders.py", line 126, in load
    source, filename, uptodate = self.get_source(environment, name)
  File "/usr/local/lib/python3.10/dist-packages/flask/templating.py", line 65, in get_source
    return self._get_source_fast(environment, template)
  File "/usr/local/lib/python3.10/dist-packages/flask/templating.py", line 99, in _get_source_fast
    raise TemplateNotFound(template)
jinja2.exceptions.TemplateNotFound: error.html
65.49.1.94 - - [01/Jul/2025 05:35:52] "GET / HTTP/1.1" 302 -
65.49.1.100 - - [01/Jul/2025 05:36:03] "GET / HTTP/1.1" 302 -
65.49.1.106 - - [01/Jul/2025 05:36:03] "GET /dashboard HTTP/1.1" 200 -
[2025-07-01 05:36:18,652] ERROR in app: Ошибка: 404 Not Found: The requested URL was not found on the server. If you entered the URL manually please check your spelling and try again.
65.49.1.94 - - [01/Jul/2025 05:36:18] "GET /favicon.ico HTTP/1.1" 500 -
Traceback (most recent call last):
  File "/usr/local/lib/python3.10/dist-packages/flask/app.py", line 917, in full_dispatch_request
    rv = self.dispatch_request()
  File "/usr/local/lib/python3.10/dist-packages/flask/app.py", line 891, in dispatch_request
    self.raise_routing_exception(req)
  File "/usr/local/lib/python3.10/dist-packages/flask/app.py", line 500, in raise_routing_exception
    raise request.routing_exception  # type: ignore[misc]
  File "/usr/local/lib/python3.10/dist-packages/flask/ctx.py", line 362, in match_request
    result = self.url_adapter.match(return_rule=True)  # type: ignore
  File "/usr/local/lib/python3.10/dist-packages/werkzeug/routing/map.py", line 629, in match
    raise NotFound() from None
werkzeug.exceptions.NotFound: 404 Not Found: The requested URL was not found on the server. If you entered the URL manually please check your spelling and try again.

During handling of the above exception, another exception occurred:

Traceback (most recent call last):
  File "/usr/local/lib/python3.10/dist-packages/flask/app.py", line 1536, in __call__
    return self.wsgi_app(environ, start_response)
  File "/usr/local/lib/python3.10/dist-packages/flask/app.py", line 1514, in wsgi_app
    response = self.handle_exception(e)
  File "/usr/local/lib/python3.10/dist-packages/flask/app.py", line 1511, in wsgi_app
    response = self.full_dispatch_request()
  File "/usr/local/lib/python3.10/dist-packages/flask/app.py", line 919, in full_dispatch_request
    rv = self.handle_user_exception(e)
  File "/usr/local/lib/python3.10/dist-packages/flask/app.py", line 802, in handle_user_exception
    return self.handle_http_exception(e)
  File "/usr/local/lib/python3.10/dist-packages/flask/app.py", line 777, in handle_http_exception
    return self.ensure_sync(handler)(e)  # type: ignore[no-any-return]
  File "/root/VFS-Global/site/app.py", line 32, in handle_exception
    return render_template("error.html", error=str(e)), 500
  File "/usr/local/lib/python3.10/dist-packages/flask/templating.py", line 149, in render_template
    template = app.jinja_env.get_or_select_template(template_name_or_list)
  File "/usr/local/lib/python3.10/dist-packages/jinja2/environment.py", line 1087, in get_or_select_template
    return self.get_template(template_name_or_list, parent, globals)
  File "/usr/local/lib/python3.10/dist-packages/jinja2/environment.py", line 1016, in get_template
    return self._load_template(name, globals)
  File "/usr/local/lib/python3.10/dist-packages/jinja2/environment.py", line 975, in _load_template
    template = self.loader.load(self, name, self.make_globals(globals))
  File "/usr/local/lib/python3.10/dist-packages/jinja2/loaders.py", line 126, in load
    source, filename, uptodate = self.get_source(environment, name)
  File "/usr/local/lib/python3.10/dist-packages/flask/templating.py", line 65, in get_source
    return self._get_source_fast(environment, template)
  File "/usr/local/lib/python3.10/dist-packages/flask/templating.py", line 99, in _get_source_fast
    raise TemplateNotFound(template)
jinja2.exceptions.TemplateNotFound: error.html
95.24.237.144 - - [01/Jul/2025 08:55:14] "GET / HTTP/1.1" 302 -
95.24.237.144 - - [01/Jul/2025 08:55:14] "GET /dashboard HTTP/1.1" 200 -
[2025-07-01 08:55:15,086] ERROR in app: Ошибка: 404 Not Found: The requested URL was not found on the server. If you entered the URL manually please check your spelling and try again.
95.24.237.144 - - [01/Jul/2025 08:55:15] "GET /favicon.ico HTTP/1.1" 500 -
Traceback (most recent call last):
  File "/usr/local/lib/python3.10/dist-packages/flask/app.py", line 917, in full_dispatch_request
    rv = self.dispatch_request()
  File "/usr/local/lib/python3.10/dist-packages/flask/app.py", line 891, in dispatch_request
    self.raise_routing_exception(req)
  File "/usr/local/lib/python3.10/dist-packages/flask/app.py", line 500, in raise_routing_exception
    raise request.routing_exception  # type: ignore[misc]
  File "/usr/local/lib/python3.10/dist-packages/flask/ctx.py", line 362, in match_request
    result = self.url_adapter.match(return_rule=True)  # type: ignore
  File "/usr/local/lib/python3.10/dist-packages/werkzeug/routing/map.py", line 629, in match
    raise NotFound() from None
werkzeug.exceptions.NotFound: 404 Not Found: The requested URL was not found on the server. If you entered the URL manually please check your spelling and try again.

During handling of the above exception, another exception occurred:

Traceback (most recent call last):
  File "/usr/local/lib/python3.10/dist-packages/flask/app.py", line 1536, in __call__
    return self.wsgi_app(environ, start_response)
  File "/usr/local/lib/python3.10/dist-packages/flask/app.py", line 1514, in wsgi_app
    response = self.handle_exception(e)
  File "/usr/local/lib/python3.10/dist-packages/flask/app.py", line 1511, in wsgi_app
    response = self.full_dispatch_request()
  File "/usr/local/lib/python3.10/dist-packages/flask/app.py", line 919, in full_dispatch_request
    rv = self.handle_user_exception(e)
  File "/usr/local/lib/python3.10/dist-packages/flask/app.py", line 802, in handle_user_exception
    return self.handle_http_exception(e)
  File "/usr/local/lib/python3.10/dist-packages/flask/app.py", line 777, in handle_http_exception
    return self.ensure_sync(handler)(e)  # type: ignore[no-any-return]
  File "/root/VFS-Global/site/app.py", line 32, in handle_exception
    return render_template("error.html", error=str(e)), 500
  File "/usr/local/lib/python3.10/dist-packages/flask/templating.py", line 149, in render_template
    template = app.jinja_env.get_or_select_template(template_name_or_list)
  File "/usr/local/lib/python3.10/dist-packages/jinja2/environment.py", line 1087, in get_or_select_template
    return self.get_template(template_name_or_list, parent, globals)
  File "/usr/local/lib/python3.10/dist-packages/jinja2/environment.py", line 1016, in get_template
    return self._load_template(name, globals)
  File "/usr/local/lib/python3.10/dist-packages/jinja2/environment.py", line 975, in _load_template
    template = self.loader.load(self, name, self.make_globals(globals))
  File "/usr/local/lib/python3.10/dist-packages/jinja2/loaders.py", line 126, in load
    source, filename, uptodate = self.get_source(environment, name)
  File "/usr/local/lib/python3.10/dist-packages/flask/templating.py", line 65, in get_source
    return self._get_source_fast(environment, template)
  File "/usr/local/lib/python3.10/dist-packages/flask/templating.py", line 99, in _get_source_fast
    raise TemplateNotFound(template)
jinja2.exceptions.TemplateNotFound: error.html
213.87.152.171 - - [01/Jul/2025 10:49:30] "GET / HTTP/1.1" 302 -
213.87.152.171 - - [01/Jul/2025 10:49:31] "GET /dashboard HTTP/1.1" 200 -
[2025-07-01 10:49:32,171] ERROR in app: Ошибка: 404 Not Found: The requested URL was not found on the server. If you entered the URL manually please check your spelling and try again.
213.87.152.171 - - [01/Jul/2025 10:49:32] "GET /favicon.ico HTTP/1.1" 500 -
Traceback (most recent call last):
  File "/usr/local/lib/python3.10/dist-packages/flask/app.py", line 917, in full_dispatch_request
    rv = self.dispatch_request()
  File "/usr/local/lib/python3.10/dist-packages/flask/app.py", line 891, in dispatch_request
    self.raise_routing_exception(req)
  File "/usr/local/lib/python3.10/dist-packages/flask/app.py", line 500, in raise_routing_exception
    raise request.routing_exception  # type: ignore[misc]
  File "/usr/local/lib/python3.10/dist-packages/flask/ctx.py", line 362, in match_request
    result = self.url_adapter.match(return_rule=True)  # type: ignore
  File "/usr/local/lib/python3.10/dist-packages/werkzeug/routing/map.py", line 629, in match
    raise NotFound() from None
werkzeug.exceptions.NotFound: 404 Not Found: The requested URL was not found on the server. If you entered the URL manually please check your spelling and try again.

During handling of the above exception, another exception occurred:

Traceback (most recent call last):
  File "/usr/local/lib/python3.10/dist-packages/flask/app.py", line 1536, in __call__
    return self.wsgi_app(environ, start_response)
  File "/usr/local/lib/python3.10/dist-packages/flask/app.py", line 1514, in wsgi_app
    response = self.handle_exception(e)
  File "/usr/local/lib/python3.10/dist-packages/flask/app.py", line 1511, in wsgi_app
    response = self.full_dispatch_request()
  File "/usr/local/lib/python3.10/dist-packages/flask/app.py", line 919, in full_dispatch_request
    rv = self.handle_user_exception(e)
  File "/usr/local/lib/python3.10/dist-packages/flask/app.py", line 802, in handle_user_exception
    return self.handle_http_exception(e)
  File "/usr/local/lib/python3.10/dist-packages/flask/app.py", line 777, in handle_http_exception
    return self.ensure_sync(handler)(e)  # type: ignore[no-any-return]
  File "/root/VFS-Global/site/app.py", line 32, in handle_exception
    return render_template("error.html", error=str(e)), 500
  File "/usr/local/lib/python3.10/dist-packages/flask/templating.py", line 149, in render_template
    template = app.jinja_env.get_or_select_template(template_name_or_list)
  File "/usr/local/lib/python3.10/dist-packages/jinja2/environment.py", line 1087, in get_or_select_template
    return self.get_template(template_name_or_list, parent, globals)
  File "/usr/local/lib/python3.10/dist-packages/jinja2/environment.py", line 1016, in get_template
    return self._load_template(name, globals)
  File "/usr/local/lib/python3.10/dist-packages/jinja2/environment.py", line 975, in _load_template
    template = self.loader.load(self, name, self.make_globals(globals))
  File "/usr/local/lib/python3.10/dist-packages/jinja2/loaders.py", line 126, in load
    source, filename, uptodate = self.get_source(environment, name)
  File "/usr/local/lib/python3.10/dist-packages/flask/templating.py", line 65, in get_source
    return self._get_source_fast(environment, template)
  File "/usr/local/lib/python3.10/dist-packages/flask/templating.py", line 99, in _get_source_fast
    raise TemplateNotFound(template)
jinja2.exceptions.TemplateNotFound: error.html
213.87.152.171 - - [01/Jul/2025 10:49:54] "GET / HTTP/1.1" 302 -
213.87.152.171 - - [01/Jul/2025 10:49:54] "GET /dashboard HTTP/1.1" 200 -
[2025-07-01 10:49:55,376] ERROR in app: Ошибка: 404 Not Found: The requested URL was not found on the server. If you entered the URL manually please check your spelling and try again.
213.87.152.171 - - [01/Jul/2025 10:49:55] "GET /favicon.ico HTTP/1.1" 500 -
Traceback (most recent call last):
  File "/usr/local/lib/python3.10/dist-packages/flask/app.py", line 917, in full_dispatch_request
    rv = self.dispatch_request()
  File "/usr/local/lib/python3.10/dist-packages/flask/app.py", line 891, in dispatch_request
    self.raise_routing_exception(req)
  File "/usr/local/lib/python3.10/dist-packages/flask/app.py", line 500, in raise_routing_exception
    raise request.routing_exception  # type: ignore[misc]
  File "/usr/local/lib/python3.10/dist-packages/flask/ctx.py", line 362, in match_request
    result = self.url_adapter.match(return_rule=True)  # type: ignore
  File "/usr/local/lib/python3.10/dist-packages/werkzeug/routing/map.py", line 629, in match
    raise NotFound() from None
werkzeug.exceptions.NotFound: 404 Not Found: The requested URL was not found on the server. If you entered the URL manually please check your spelling and try again.

During handling of the above exception, another exception occurred:

Traceback (most recent call last):
  File "/usr/local/lib/python3.10/dist-packages/flask/app.py", line 1536, in __call__
    return self.wsgi_app(environ, start_response)
  File "/usr/local/lib/python3.10/dist-packages/flask/app.py", line 1514, in wsgi_app
    response = self.handle_exception(e)
  File "/usr/local/lib/python3.10/dist-packages/flask/app.py", line 1511, in wsgi_app
    response = self.full_dispatch_request()
  File "/usr/local/lib/python3.10/dist-packages/flask/app.py", line 919, in full_dispatch_request
    rv = self.handle_user_exception(e)
  File "/usr/local/lib/python3.10/dist-packages/flask/app.py", line 802, in handle_user_exception
    return self.handle_http_exception(e)
  File "/usr/local/lib/python3.10/dist-packages/flask/app.py", line 777, in handle_http_exception
    return self.ensure_sync(handler)(e)  # type: ignore[no-any-return]
  File "/root/VFS-Global/site/app.py", line 32, in handle_exception
    return render_template("error.html", error=str(e)), 500
  File "/usr/local/lib/python3.10/dist-packages/flask/templating.py", line 149, in render_template
    template = app.jinja_env.get_or_select_template(template_name_or_list)
  File "/usr/local/lib/python3.10/dist-packages/jinja2/environment.py", line 1087, in get_or_select_template
    return self.get_template(template_name_or_list, parent, globals)
  File "/usr/local/lib/python3.10/dist-packages/jinja2/environment.py", line 1016, in get_template
    return self._load_template(name, globals)
  File "/usr/local/lib/python3.10/dist-packages/jinja2/environment.py", line 975, in _load_template
    template = self.loader.load(self, name, self.make_globals(globals))
  File "/usr/local/lib/python3.10/dist-packages/jinja2/loaders.py", line 126, in load
    source, filename, uptodate = self.get_source(environment, name)
  File "/usr/local/lib/python3.10/dist-packages/flask/templating.py", line 65, in get_source
    return self._get_source_fast(environment, template)
  File "/usr/local/lib/python3.10/dist-packages/flask/templating.py", line 99, in _get_source_fast
    raise TemplateNotFound(template)
jinja2.exceptions.TemplateNotFound: error.html
213.87.148.59 - - [01/Jul/2025 10:49:57] "GET / HTTP/1.1" 302 -
213.87.148.59 - - [01/Jul/2025 10:49:57] "GET /dashboard HTTP/1.1" 200 -
[2025-07-01 10:49:57,937] ERROR in app: Ошибка: 404 Not Found: The requested URL was not found on the server. If you entered the URL manually please check your spelling and try again.
213.87.148.59 - - [01/Jul/2025 10:49:57] "GET /favicon.ico HTTP/1.1" 500 -
Traceback (most recent call last):
  File "/usr/local/lib/python3.10/dist-packages/flask/app.py", line 917, in full_dispatch_request
    rv = self.dispatch_request()
  File "/usr/local/lib/python3.10/dist-packages/flask/app.py", line 891, in dispatch_request
    self.raise_routing_exception(req)
  File "/usr/local/lib/python3.10/dist-packages/flask/app.py", line 500, in raise_routing_exception
    raise request.routing_exception  # type: ignore[misc]
  File "/usr/local/lib/python3.10/dist-packages/flask/ctx.py", line 362, in match_request
    result = self.url_adapter.match(return_rule=True)  # type: ignore
  File "/usr/local/lib/python3.10/dist-packages/werkzeug/routing/map.py", line 629, in match
    raise NotFound() from None
werkzeug.exceptions.NotFound: 404 Not Found: The requested URL was not found on the server. If you entered the URL manually please check your spelling and try again.

During handling of the above exception, another exception occurred:

Traceback (most recent call last):
  File "/usr/local/lib/python3.10/dist-packages/flask/app.py", line 1536, in __call__
    return self.wsgi_app(environ, start_response)
  File "/usr/local/lib/python3.10/dist-packages/flask/app.py", line 1514, in wsgi_app
    response = self.handle_exception(e)
  File "/usr/local/lib/python3.10/dist-packages/flask/app.py", line 1511, in wsgi_app
    response = self.full_dispatch_request()
  File "/usr/local/lib/python3.10/dist-packages/flask/app.py", line 919, in full_dispatch_request
    rv = self.handle_user_exception(e)
  File "/usr/local/lib/python3.10/dist-packages/flask/app.py", line 802, in handle_user_exception
    return self.handle_http_exception(e)
  File "/usr/local/lib/python3.10/dist-packages/flask/app.py", line 777, in handle_http_exception
    return self.ensure_sync(handler)(e)  # type: ignore[no-any-return]
  File "/root/VFS-Global/site/app.py", line 32, in handle_exception
    return render_template("error.html", error=str(e)), 500
  File "/usr/local/lib/python3.10/dist-packages/flask/templating.py", line 149, in render_template
    template = app.jinja_env.get_or_select_template(template_name_or_list)
  File "/usr/local/lib/python3.10/dist-packages/jinja2/environment.py", line 1087, in get_or_select_template
    return self.get_template(template_name_or_list, parent, globals)
  File "/usr/local/lib/python3.10/dist-packages/jinja2/environment.py", line 1016, in get_template
    return self._load_template(name, globals)
  File "/usr/local/lib/python3.10/dist-packages/jinja2/environment.py", line 975, in _load_template
    template = self.loader.load(self, name, self.make_globals(globals))
  File "/usr/local/lib/python3.10/dist-packages/jinja2/loaders.py", line 126, in load
    source, filename, uptodate = self.get_source(environment, name)
  File "/usr/local/lib/python3.10/dist-packages/flask/templating.py", line 65, in get_source
    return self._get_source_fast(environment, template)
  File "/usr/local/lib/python3.10/dist-packages/flask/templating.py", line 99, in _get_source_fast
    raise TemplateNotFound(template)
jinja2.exceptions.TemplateNotFound: error.html
 * Detected change in '/root/VFS-Global/tg-bot.py', reloading
 * Restarting with stat
 * Debugger is active!
 * Debugger PIN: 530-417-129
213.87.148.59 - - [01/Jul/2025 11:27:48] "GET / HTTP/1.1" 302 -
213.87.148.59 - - [01/Jul/2025 11:27:49] "GET /dashboard HTTP/1.1" 200 -
[2025-07-01 11:27:49,406] ERROR in app: Ошибка: 404 Not Found: The requested URL was not found on the server. If you entered the URL manually please check your spelling and try again.
213.87.148.59 - - [01/Jul/2025 11:27:49] "GET /favicon.ico HTTP/1.1" 500 -
Traceback (most recent call last):
  File "/usr/local/lib/python3.10/dist-packages/flask/app.py", line 917, in full_dispatch_request
    rv = self.dispatch_request()
  File "/usr/local/lib/python3.10/dist-packages/flask/app.py", line 891, in dispatch_request
    self.raise_routing_exception(req)
  File "/usr/local/lib/python3.10/dist-packages/flask/app.py", line 500, in raise_routing_exception
    raise request.routing_exception  # type: ignore[misc]
  File "/usr/local/lib/python3.10/dist-packages/flask/ctx.py", line 362, in match_request
    result = self.url_adapter.match(return_rule=True)  # type: ignore
  File "/usr/local/lib/python3.10/dist-packages/werkzeug/routing/map.py", line 629, in match
    raise NotFound() from None
werkzeug.exceptions.NotFound: 404 Not Found: The requested URL was not found on the server. If you entered the URL manually please check your spelling and try again.

During handling of the above exception, another exception occurred:

Traceback (most recent call last):
  File "/usr/local/lib/python3.10/dist-packages/flask/app.py", line 1536, in __call__
    return self.wsgi_app(environ, start_response)
  File "/usr/local/lib/python3.10/dist-packages/flask/app.py", line 1514, in wsgi_app
    response = self.handle_exception(e)
  File "/usr/local/lib/python3.10/dist-packages/flask/app.py", line 1511, in wsgi_app
    response = self.full_dispatch_request()
  File "/usr/local/lib/python3.10/dist-packages/flask/app.py", line 919, in full_dispatch_request
    rv = self.handle_user_exception(e)
  File "/usr/local/lib/python3.10/dist-packages/flask/app.py", line 802, in handle_user_exception
    return self.handle_http_exception(e)
  File "/usr/local/lib/python3.10/dist-packages/flask/app.py", line 777, in handle_http_exception
    return self.ensure_sync(handler)(e)  # type: ignore[no-any-return]
  File "/root/VFS-Global/site/app.py", line 32, in handle_exception
    return render_template("error.html", error=str(e)), 500
  File "/usr/local/lib/python3.10/dist-packages/flask/templating.py", line 149, in render_template
    template = app.jinja_env.get_or_select_template(template_name_or_list)
  File "/usr/local/lib/python3.10/dist-packages/jinja2/environment.py", line 1087, in get_or_select_template
    return self.get_template(template_name_or_list, parent, globals)
  File "/usr/local/lib/python3.10/dist-packages/jinja2/environment.py", line 1016, in get_template
    return self._load_template(name, globals)
  File "/usr/local/lib/python3.10/dist-packages/jinja2/environment.py", line 975, in _load_template
    template = self.loader.load(self, name, self.make_globals(globals))
  File "/usr/local/lib/python3.10/dist-packages/jinja2/loaders.py", line 126, in load
    source, filename, uptodate = self.get_source(environment, name)
  File "/usr/local/lib/python3.10/dist-packages/flask/templating.py", line 65, in get_source
    return self._get_source_fast(environment, template)
  File "/usr/local/lib/python3.10/dist-packages/flask/templating.py", line 99, in _get_source_fast
    raise TemplateNotFound(template)
jinja2.exceptions.TemplateNotFound: error.html
213.87.148.59 - - [01/Jul/2025 12:13:44] "GET / HTTP/1.1" 302 -
213.87.148.59 - - [01/Jul/2025 12:13:44] "GET /dashboard HTTP/1.1" 200 -
[2025-07-01 12:13:44,604] ERROR in app: Ошибка: 404 Not Found: The requested URL was not found on the server. If you entered the URL manually please check your spelling and try again.
213.87.148.59 - - [01/Jul/2025 12:13:44] "GET /favicon.ico HTTP/1.1" 500 -
Traceback (most recent call last):
  File "/usr/local/lib/python3.10/dist-packages/flask/app.py", line 917, in full_dispatch_request
    rv = self.dispatch_request()
  File "/usr/local/lib/python3.10/dist-packages/flask/app.py", line 891, in dispatch_request
    self.raise_routing_exception(req)
  File "/usr/local/lib/python3.10/dist-packages/flask/app.py", line 500, in raise_routing_exception
    raise request.routing_exception  # type: ignore[misc]
  File "/usr/local/lib/python3.10/dist-packages/flask/ctx.py", line 362, in match_request
    result = self.url_adapter.match(return_rule=True)  # type: ignore
  File "/usr/local/lib/python3.10/dist-packages/werkzeug/routing/map.py", line 629, in match
    raise NotFound() from None
werkzeug.exceptions.NotFound: 404 Not Found: The requested URL was not found on the server. If you entered the URL manually please check your spelling and try again.

During handling of the above exception, another exception occurred:

Traceback (most recent call last):
  File "/usr/local/lib/python3.10/dist-packages/flask/app.py", line 1536, in __call__
    return self.wsgi_app(environ, start_response)
  File "/usr/local/lib/python3.10/dist-packages/flask/app.py", line 1514, in wsgi_app
    response = self.handle_exception(e)
  File "/usr/local/lib/python3.10/dist-packages/flask/app.py", line 1511, in wsgi_app
    response = self.full_dispatch_request()
  File "/usr/local/lib/python3.10/dist-packages/flask/app.py", line 919, in full_dispatch_request
    rv = self.handle_user_exception(e)
  File "/usr/local/lib/python3.10/dist-packages/flask/app.py", line 802, in handle_user_exception
    return self.handle_http_exception(e)
  File "/usr/local/lib/python3.10/dist-packages/flask/app.py", line 777, in handle_http_exception
    return self.ensure_sync(handler)(e)  # type: ignore[no-any-return]
  File "/root/VFS-Global/site/app.py", line 32, in handle_exception
    return render_template("error.html", error=str(e)), 500
  File "/usr/local/lib/python3.10/dist-packages/flask/templating.py", line 149, in render_template
    template = app.jinja_env.get_or_select_template(template_name_or_list)
  File "/usr/local/lib/python3.10/dist-packages/jinja2/environment.py", line 1087, in get_or_select_template
    return self.get_template(template_name_or_list, parent, globals)
  File "/usr/local/lib/python3.10/dist-packages/jinja2/environment.py", line 1016, in get_template
    return self._load_template(name, globals)
  File "/usr/local/lib/python3.10/dist-packages/jinja2/environment.py", line 975, in _load_template
    template = self.loader.load(self, name, self.make_globals(globals))
  File "/usr/local/lib/python3.10/dist-packages/jinja2/loaders.py", line 126, in load
    source, filename, uptodate = self.get_source(environment, name)
  File "/usr/local/lib/python3.10/dist-packages/flask/templating.py", line 65, in get_source
    return self._get_source_fast(environment, template)
  File "/usr/local/lib/python3.10/dist-packages/flask/templating.py", line 99, in _get_source_fast
    raise TemplateNotFound(template)
jinja2.exceptions.TemplateNotFound: error.html
185.100.87.136 - - [01/Jul/2025 12:38:14] code 400, message Bad HTTP/0.9 request type ('\x00\x00\x00\x11\x00\x00\x01é\x00\x01\x00\x00\x00ÿÿÿÿ\x01\x00\x00\x00\x00\x00\x00\x00')
185.100.87.136 - - [01/Jul/2025 12:38:14] "\x00\x00\x00\x11\x00\x00\x01é\x00\x01\x00\x00\x00ÿÿÿÿ\x01\x00\x00\x00\x00\x00\x00\x00\x0c\x02\x00\x00\x00\x10MyCustomAssembly\x05\x01\x00\x00\x00" HTTPStatus.BAD_REQUEST -
3.132.23.201 - - [01/Jul/2025 13:50:57] "GET / HTTP/1.1" 302 -
3.132.23.201 - - [01/Jul/2025 13:50:57] "GET /dashboard HTTP/1.1" 200 -
3.132.23.201 - - [01/Jul/2025 13:53:04] "GET / HTTP/1.1" 302 -
3.132.23.201 - - [01/Jul/2025 13:54:50] code 400, message Bad request version ('À\x14À')
3.132.23.201 - - [01/Jul/2025 13:54:50] "\x16\x03\x01\x00{\x01\x00\x00w\x03\x03^\x967üý\x09ã¶ïæpP¡^úôrô)\x9aÏ\x81@úOÍzh«ÁÖo\x00\x00\x1aÀ/À+À\x11À\x07À\x13À\x09À\x14À" HTTPStatus.BAD_REQUEST -
3.132.23.201 - - [01/Jul/2025 13:56:01] code 400, message Bad request syntax ('SSH-2.0-Go')
3.132.23.201 - - [01/Jul/2025 13:56:01] "SSH-2.0-Go" HTTPStatus.BAD_REQUEST -
3.132.23.201 - - [01/Jul/2025 13:57:07] code 400, message Bad request version ('À\x14À')
3.132.23.201 - - [01/Jul/2025 13:57:07] "\x16\x03\x01\x00{\x01\x00\x00w\x03\x03Îx\x1c#\x114J\x89\x00yÄ0Kõ\x7f\x1d©\x90\x8a±e'»\x8a_§%ñ\x85}\x91\x0e\x00\x00\x1aÀ/À+À\x11À\x07À\x13À\x09À\x14À" HTTPStatus.BAD_REQUEST -
89.248.172.16 - - [01/Jul/2025 14:05:40] "GET / HTTP/1.1" 302 -
89.248.172.16 - - [01/Jul/2025 14:05:40] "GET /dashboard HTTP/1.1" 200 -
[2025-07-01 14:05:40,401] ERROR in app: Ошибка: 404 Not Found: The requested URL was not found on the server. If you entered the URL manually please check your spelling and try again.
89.248.172.16 - - [01/Jul/2025 14:05:40] "GET /favicon.ico HTTP/1.1" 500 -
Traceback (most recent call last):
  File "/usr/local/lib/python3.10/dist-packages/flask/app.py", line 917, in full_dispatch_request
    rv = self.dispatch_request()
  File "/usr/local/lib/python3.10/dist-packages/flask/app.py", line 891, in dispatch_request
    self.raise_routing_exception(req)
  File "/usr/local/lib/python3.10/dist-packages/flask/app.py", line 500, in raise_routing_exception
    raise request.routing_exception  # type: ignore[misc]
  File "/usr/local/lib/python3.10/dist-packages/flask/ctx.py", line 362, in match_request
    result = self.url_adapter.match(return_rule=True)  # type: ignore
  File "/usr/local/lib/python3.10/dist-packages/werkzeug/routing/map.py", line 629, in match
    raise NotFound() from None
werkzeug.exceptions.NotFound: 404 Not Found: The requested URL was not found on the server. If you entered the URL manually please check your spelling and try again.

During handling of the above exception, another exception occurred:

Traceback (most recent call last):
  File "/usr/local/lib/python3.10/dist-packages/flask/app.py", line 1536, in __call__
    return self.wsgi_app(environ, start_response)
  File "/usr/local/lib/python3.10/dist-packages/flask/app.py", line 1514, in wsgi_app
    response = self.handle_exception(e)
  File "/usr/local/lib/python3.10/dist-packages/flask/app.py", line 1511, in wsgi_app
    response = self.full_dispatch_request()
  File "/usr/local/lib/python3.10/dist-packages/flask/app.py", line 919, in full_dispatch_request
    rv = self.handle_user_exception(e)
  File "/usr/local/lib/python3.10/dist-packages/flask/app.py", line 802, in handle_user_exception
    return self.handle_http_exception(e)
  File "/usr/local/lib/python3.10/dist-packages/flask/app.py", line 777, in handle_http_exception
    return self.ensure_sync(handler)(e)  # type: ignore[no-any-return]
  File "/root/VFS-Global/site/app.py", line 32, in handle_exception
    return render_template("error.html", error=str(e)), 500
  File "/usr/local/lib/python3.10/dist-packages/flask/templating.py", line 149, in render_template
    template = app.jinja_env.get_or_select_template(template_name_or_list)
  File "/usr/local/lib/python3.10/dist-packages/jinja2/environment.py", line 1087, in get_or_select_template
    return self.get_template(template_name_or_list, parent, globals)
  File "/usr/local/lib/python3.10/dist-packages/jinja2/environment.py", line 1016, in get_template
    return self._load_template(name, globals)
  File "/usr/local/lib/python3.10/dist-packages/jinja2/environment.py", line 975, in _load_template
    template = self.loader.load(self, name, self.make_globals(globals))
  File "/usr/local/lib/python3.10/dist-packages/jinja2/loaders.py", line 126, in load
    source, filename, uptodate = self.get_source(environment, name)
  File "/usr/local/lib/python3.10/dist-packages/flask/templating.py", line 65, in get_source
    return self._get_source_fast(environment, template)
  File "/usr/local/lib/python3.10/dist-packages/flask/templating.py", line 99, in _get_source_fast
    raise TemplateNotFound(template)
jinja2.exceptions.TemplateNotFound: error.html
 * Detected change in '/root/VFS-Global/vfs_parser/monitoring.py', reloading
 * Restarting with stat
 * Debugger is active!
 * Debugger PIN: 530-417-129
 * Detected change in '/root/VFS-Global/vfs_parser/monitoring.py', reloading
 * Restarting with stat
 * Debugger is active!
 * Debugger PIN: 530-417-129
